[2022-10-02 13:52:14,960: ERROR/ForkPoolWorker-6] Task domain_add[9e6c9ea8-209c-483a-aa25-a046775f37cf] raised unexpected: InvalidSchema("No connection adapters were found for '&authinfo=:&func=site.edit&sok=ok&site_name=ffyyee.xyz&site_aliases=&site_email=webmaster@ffyyee.xyz&site_home=www/instateleport.ru&secure=on&site_redirect_http=on&site_ssl_cert=ssl_not_used&site_php_mode=php_not_used'")
Traceback (most recent call last):
  File "/root/instateleport/getsub/lib/python3.9/site-packages/celery/app/trace.py", line 385, in trace_task
    R = retval = fun(*args, **kwargs)
  File "/root/instateleport/getsub/lib/python3.9/site-packages/celery/app/trace.py", line 650, in __protected_call__
    return self.run(*args, **kwargs)
  File "/root/instateleport/apps/subscribe_pages/task.py", line 50, in domain_add
    response = ispmanager.add_webdomain(domain)
  File "/root/instateleport/apps/subscribe_pages/ispmanager_api/api.py", line 14, in add_webdomain
    return requests.get(
  File "/root/instateleport/getsub/lib/python3.9/site-packages/requests/api.py", line 76, in get
    return request('get', url, params=params, **kwargs)
  File "/root/instateleport/getsub/lib/python3.9/site-packages/requests/api.py", line 61, in request
    return session.request(method=method, url=url, **kwargs)
  File "/root/instateleport/getsub/lib/python3.9/site-packages/requests/sessions.py", line 530, in request
    resp = self.send(prep, **send_kwargs)
  File "/root/instateleport/getsub/lib/python3.9/site-packages/requests/sessions.py", line 637, in send
    adapter = self.get_adapter(url=request.url)
  File "/root/instateleport/getsub/lib/python3.9/site-packages/requests/sessions.py", line 728, in get_adapter
    raise InvalidSchema("No connection adapters were found for {!r}".format(url))
requests.exceptions.InvalidSchema: No connection adapters were found for '&authinfo=:&func=site.edit&sok=ok&site_name=ffyyee.xyz&site_aliases=&site_email=webmaster@ffyyee.xyz&site_home=www/instateleport.ru&secure=on&site_redirect_http=on&site_ssl_cert=ssl_not_used&site_php_mode=php_not_used'
[2022-10-02 13:52:14,968: INFO/ForkPoolWorker-6] Task save_instagram_info[9fc8ae88-a1e1-4766-a68a-2ba7b792857e] succeeded in 0.001108144000681932s: None
[2022-10-03 13:05:11,568: INFO/ForkPoolWorker-6] Task save_instagram_info[cddfcd98-4c8f-4f67-9ee6-b0335df1221b] succeeded in 0.0032846830000039517s: None
[2022-10-06 06:05:21,371: ERROR/ForkPoolWorker-6] Task domain_add[0e610ab9-8ba3-4bb8-a7bd-537b9b75ffea] raised unexpected: InvalidSchema("No connection adapters were found for '&authinfo=:&func=site.edit&sok=ok&site_name=ffyyee.xyz&site_aliases=&site_email=webmaster@ffyyee.xyz&site_home=www/instateleport.ru&secure=on&site_redirect_http=on&site_ssl_cert=ssl_not_used&site_php_mode=php_not_used'")
Traceback (most recent call last):
  File "/root/instateleport/getsub/lib/python3.9/site-packages/celery/app/trace.py", line 385, in trace_task
    R = retval = fun(*args, **kwargs)
  File "/root/instateleport/getsub/lib/python3.9/site-packages/celery/app/trace.py", line 650, in __protected_call__
    return self.run(*args, **kwargs)
  File "/root/instateleport/apps/subscribe_pages/task.py", line 50, in domain_add
    response = ispmanager.add_webdomain(domain)
  File "/root/instateleport/apps/subscribe_pages/ispmanager_api/api.py", line 14, in add_webdomain
    return requests.get(
  File "/root/instateleport/getsub/lib/python3.9/site-packages/requests/api.py", line 76, in get
    return request('get', url, params=params, **kwargs)
  File "/root/instateleport/getsub/lib/python3.9/site-packages/requests/api.py", line 61, in request
    return session.request(method=method, url=url, **kwargs)
  File "/root/instateleport/getsub/lib/python3.9/site-packages/requests/sessions.py", line 530, in request
    resp = self.send(prep, **send_kwargs)
  File "/root/instateleport/getsub/lib/python3.9/site-packages/requests/sessions.py", line 637, in send
    adapter = self.get_adapter(url=request.url)
  File "/root/instateleport/getsub/lib/python3.9/site-packages/requests/sessions.py", line 728, in get_adapter
    raise InvalidSchema("No connection adapters were found for {!r}".format(url))
requests.exceptions.InvalidSchema: No connection adapters were found for '&authinfo=:&func=site.edit&sok=ok&site_name=ffyyee.xyz&site_aliases=&site_email=webmaster@ffyyee.xyz&site_home=www/instateleport.ru&secure=on&site_redirect_http=on&site_ssl_cert=ssl_not_used&site_php_mode=php_not_used'
[2022-10-06 07:05:07,791: INFO/ForkPoolWorker-6] Task save_instagram_info[6ed74945-e074-4367-bc49-3be4b7ebf05b] succeeded in 0.005659832997480407s: None
[2022-10-07 16:47:06,693: WARNING/ForkPoolWorker-6] /root/instateleport/getsub/lib/python3.9/site-packages/urllib3/connectionpool.py:979: InsecureRequestWarning: Unverified HTTPS request is being made to host '62.109.7.205'. Adding certificate verification is strongly advised. See: https://urllib3.readthedocs.io/en/latest/advanced-usage.html#ssl-warnings
  warnings.warn(
[2022-10-07 16:47:07,209: WARNING/ForkPoolWorker-6] /root/instateleport/getsub/lib/python3.9/site-packages/urllib3/connectionpool.py:979: InsecureRequestWarning: Unverified HTTPS request is being made to host '62.109.7.205'. Adding certificate verification is strongly advised. See: https://urllib3.readthedocs.io/en/latest/advanced-usage.html#ssl-warnings
  warnings.warn(
[2022-10-07 16:47:07,211: WARNING/ForkPoolWorker-6] 2022-10-07 16:47:07 -- add_cert: ffyyee.xyz - <Response [404]>

[2022-10-07 16:47:07,213: INFO/ForkPoolWorker-6] Task domain_add[925cf3e0-8fc9-45f3-b326-d5c2f6821e1f] succeeded in 0.5366188930000035s: None
[2022-10-07 17:05:13,144: INFO/ForkPoolWorker-6] Task save_instagram_info[59f18335-5ba5-4099-8f39-e7d93709c684] succeeded in 0.004587957000012466s: None
[2022-10-18 08:05:07,462: INFO/ForkPoolWorker-6] Task save_instagram_info[f82273b1-01fc-4abb-af18-ed2922a89dc1] succeeded in 0.01190395699813962s: None
[2022-10-19 10:05:00,538: INFO/ForkPoolWorker-6] Task save_instagram_info[22b186be-a84e-4def-acc1-3b6c033a684b] succeeded in 0.003733725054189563s: None
[2022-10-19 10:05:18,301: INFO/ForkPoolWorker-6] Task save_instagram_info[9509858d-52c9-4cd3-9c2f-2d9ce9ed18b1] succeeded in 0.0010521049844101071s: None
[2022-10-21 06:05:53,421: WARNING/ForkPoolWorker-6] /var/www/www-root/data/www/instateleport.ru/getsub/lib/python3.9/site-packages/urllib3/connectionpool.py:979: InsecureRequestWarning: Unverified HTTPS request is being made to host '62.109.7.205'. Adding certificate verification is strongly advised. See: https://urllib3.readthedocs.io/en/latest/advanced-usage.html#ssl-warnings
  warnings.warn(
[2022-10-21 06:05:53,889: WARNING/ForkPoolWorker-6] /var/www/www-root/data/www/instateleport.ru/getsub/lib/python3.9/site-packages/urllib3/connectionpool.py:979: InsecureRequestWarning: Unverified HTTPS request is being made to host '62.109.7.205'. Adding certificate verification is strongly advised. See: https://urllib3.readthedocs.io/en/latest/advanced-usage.html#ssl-warnings
  warnings.warn(
[2022-10-21 06:05:54,274: INFO/ForkPoolWorker-6] Task domain_add[3c9c8368-bbf4-4aa2-b2d8-959bb6fcf2a6] succeeded in 0.8878556119743735s: None
[2022-10-21 13:05:10,471: INFO/ForkPoolWorker-6] Task save_instagram_info[75e389a1-eb5e-47f6-af98-4e8656882f8a] succeeded in 0.0034496060106903315s: None
